Workbook

Sheet CUENTA GENERAL
C2: =SUM(C5:C133) -> 2930596.2
B4: CLIENTE | C4: MONTO | E4: EntregadoenMexico
B5: AB | C5: =AB!M1 -> 1268479 | E5: Comisiones Salo
B6: SALOMON JASQUI | C6: ='SALOMON JASQUI'!O260 -> 351586.37
B7: YOSEF | C7: =YOSEF!P1 -> 381370
B8: ELIAS LEVY | C8: ='ELIAS LEVY'!O1 -> 244415
B9: LUCK | C9: =LUCK!P1 -> 92057
B10: MAN | C10: =MAN!O1 -> 50110.91
B11: JHK | C11: =JHK!O1 -> 68500
B12: BH | C12: =BH!L1 -> 73800
B13: SKM | C13: =SKM!O1 -> 63860
B14: MNS | C14: =MNS!N1 -> 66680
B15: RED | C15: =RED!P1 -> 40680
B16: ELJA | C16: =ELJA!N1 -> 62950
B17: MERCURIO | C17: =MERCURIO!N1 -> 37250
B18: AASZ ISAMAR | C18: ='AASZ '!P1 -> 36400
B19: IHE | C19: =IHE!N1 -> 12650
B20: HHB | C20: =HHB!N1 -> 19337
B21: KOBI | C21: =KOBI!O1 -> 14600
B22: JERARKYNG | C22: =JERARKYNG!N1 -> 0
B23: GLAM | C23: =GLAM!P1 -> 8280
B24: ANHERST | C24: =ANHERST!N1 -> 15700
B25: JAZ | C25: =JAZ!N1 -> 7500
B26: DACH | C26: =DACH!O1 -> 6850
B27: MOSHE TUACHI | C27: ='MOSHE TUACHI'!N1 -> 5900
B28: NUDU | C28: =NUDU!K1 -> 0
B29: BENA | C29: =BENA!O1 -> 3312.25
B30: SUPRA | C30: =SUPRA!N1 -> 0
B31: JM | C31: =JM!L1 -> 0
B32: MARIO EMILIANO | C32: ='MARIO EMILIANO'!O1 -> 0
B33: JIV | C33: =JIV!O1 -> 0
B34: INA | C34: =INA!N1 -> 0
B35: JOSHUA CREDI | C35: ='JOSHUA CREDI'!L1 -> 0
B36: JACK LEVY | C36: ='JACK LEVY'!O1 -> 0
B37: ALEJANDRO | C37: =ALEJANDRO!M1 -> 0
B38: CATTAN | C38: =CATTAN!P1 -> 0
B39: YTM | C39: =YTM!O1 -> 0
B40: ANM | C40: =ANM!O1 -> 0
B41: ABEYC | C41: =M!O1 -> 0
B42: LU | C42: =LU!N1 -> 0
...

Sheet JM
L1: =SUM(L3:L119) -> 0 | N1: =(SUM(K3:K60)-SUM(O4:O4)) -> 0
A2: REF/INV NO | B2: CUSTOMER | C2: CUSTOMER FOR | D2: BL | E2: CONTAINER | F2: ETD | G2: ETA | H2: SHIPPING LINE | I2: POL | J2: POD | K2: BILL AMT
N3: DATE | O3: PAY

Sheet AB
M1: =SUM(M3:M300)-SUM(Q4:Q100) -> 1268479
A2: REF/INV NO | B2: CUSTOMER | C2: CUSTOMER FOR | D2: CONTAINER | E2: ETD | F2: ETA | G2: SHIPPING LINE | H2: POL | I2: POD | J2: TOTAL COST | K2: EXW | L2: RAIL/TRUCK | M2: BILL AMT
A3: MLO-AB26001 | B3: JAIME ABADI | C3: MLO-AB | D3: TCNU2653972 | E3: 46043 | F3: 46076 | G3: CMA | H3: NINGBO | I3: HOUSTON , TEXAS, US | J3: 3750 | L3: - | M3: 3750 | N3: 0 | P3: DATE | Q3: PAY
A4: MLO-AB26002 | B4: JAIME ABADI | C4: MLO-AB | D4: GCXU5309377 | E4: 46043 | F4: 46076 | G4: CMA | H4: NINGBO | I4: HOUSTON , TEXAS, US | J4: 3750 | L4: - | M4: 3750 | N4: 0 | P4: 46177 | Q4: 22250
A5: MLO-AB26005 | B5: JAIME ABADI | C5: MLO-AB | D5: SEGU6355882 | E5: 46046 | F5: 46076 | G5: CMA | H5: NINGBO | I5: HOUSTON , TEXAS, US | J5: 3750 | L5: - | M5: 3750 | N5: 0 | P5: 46241 | Q5: 35700
A6: MLO-AB26006 | B6: JAIME ABADI | C6: MLO-AB | D6: ECMU5712849 | E6: 46046 | F6: 46076 | G6: CMA | H6: NINGBO | I6: HOUSTON , TEXAS, US | J6: 3750 | L6: - | M6: 3750 | N6: 0 | P6: 46254 | Q6: 36650
A7: MLO-AB26004 | B7: JAIME ABADI | C7: MLO-AB | D7: TGBU5188869 | E7: 46051 | F7: 46082 | G7: CMA | H7: NINGBO | I7: HOUSTON , TEXAS, US | J7: 3750 | L7: - | M7: 3750 | N7: 0 | P7: 46283 | Q7: 61840
A8: MLO-AB26003 | B8: JAIME ABADI | C8: MLO-AB | D8: ZCSU6874873 | E8: 46058 | F8: 46084 | G8: ZIM | H8: NINGBO | I8: HOUSTON , TEXAS, US | J8: 3500 | L8: - | M8: 3500 | N8: 0 | P8: 46213 | Q8: 40160
A9: MLO-AB26007 | B9: JAIME ABADI | C9: MLO-AB | D9: JXLU6174083 | E9: 46061 | F9: 46109 | G9: ZIM | H9: NINGBO | I9: HOUSTON , TEXAS, US | J9: 3400 | L9: - | M9: 3400 | N9: 0
A10: MLO-AB26017 | B10: JAIME ABADI | C10: MLO-AB | D10: MRSU7555239 | E10: 46126 | F10: 46143 | G10: MSK | H10: SHANGHAI | I10: PANTACO | J10: 3000 | L10: 1700 | M10: =SUM(J10:L10) -> 4700 | N10: 0
A11: MLO-AB26027 | B11: JAIME ABADI | C11: MLO-AB | D11: MSNU7430873 | E11: 46137 | F11: 46143 | G11: MSC | H11: NINGBO | I11: PANTACO | J11: 3100 | L11: 1700 | M11: =SUM(J11:L11) -> 4800 | N11: 0
A12: MLO-AB26008 | B12: JAIME ABADI | C12: TECNOMUNDO | D12: MRSU6332539 | E12: 46112 | F12: 46146 | G12: MSK | H12: SHANGHAI | I12: PANTACO | J12: 3100 | L12: 1700 | M12: =SUM(J12:L12) -> 4800 | N12: 0
A13: MLO-AB26009 | B13: JAIME ABADI | C13: TECNOMUNDO | D13: UETU8153693 | E13: 46112 | F13: 46146 | G13: MSK | H13: SHANGHAI | I13: PANTACO | J13: 3100 | L13: 1700 | M13: =SUM(J13:L13) -> 4800 | N13: 0
A14: MLO-AB26010 | B14: JAIME ABADI | C14: TECNOMUNDO | D14: UETU8361969 | E14: 46112 | F14: 46146 | G14: MSK | H14: SHANGHAI | I14: PANTACO | J14: 3100 | L14: 1700 | M14: =SUM(J14:L14) -> 4800 | N14: 0
A15: MLO-AB26019 | B15: JAIME ABADI | C15: SALOMON | D15: CSNU8819812 | E15: 46120 | F15: 46150 | G15: COSCO | H15: NINGBO | I15: HOUSTON , TEXAS, US | J15: 4200 | L15: - | M15: =SUM(J15:L15) -> 4200 | N15: 0
A16: MLO-AB26020 | B16: JAIME ABADI | C16: SALOMON | D16: CSNU8592190 | E16: 46120 | F16: 46150 | G16: COSCO | H16: NINGBO | I16: HOUSTON , TEXAS, US | J16: 4200 | L16: - | M16: =SUM(J16:L16) -> 4200 | N16: 0
A17: MLO-AB26015 | B17: JAIME ABADI | C17: TECNOMUNDO | D17: MRKU5332439 | E17: 46115 | F17: 46153 | G17: MSK | H17: NINGBO | I17: LAZARO CARDENAS,MX | J17: 3300 | M17: =SUM(J17:L17) -> 3300 | N17: -1700
A18: MLO-AB26018 | B18: JAIME ABADI | C18: SALOMON | D18: KSSU1002560 | E18: 46124 | F18: 46154 | G18: ZIM | H18: NINGBO | I18: HOUSTON , TEXAS, US | J18: 4200 | L18: - | M18: =SUM(J18:L18) -> 4200 | N18: 0
A19: MLO-AB26011 | B19: JAIME ABADI | C19: TECNOMUNDO | D19: MSKU1419888 | E19: 46119 | F19: 46158 | G19: MSK | H19: SHANGHAI | I19: PANTACO | J19: 3100 | L19: 1700 | M19: =SUM(J19:L19) -> 4800 | N19: 0
A20: MLO-AB26012 | B20: JAIME ABADI | C20: TECNOMUNDO | D20: MRSU6794516 | E20: 46119 | F20: 46158 | G20: MSK | H20: SHANGHAI | I20: PANTACO | J20: 3100 | L20: 1700 | M20: =SUM(J20:L20) -> 4800 | N20: 0
A21: MLO-AB26013 | B21: JAIME ABADI | C21: TECNOMUNDO | D21: HASU4320966 | E21: 46119 | F21: 46158 | G21: MSK | H21: SHANGHAI | I21: PANTACO | J21: 3100 | L21: 1700 | M21: =SUM(J21:L21) -> 4800 | N21: 0
A22: MLO-AB26014 | B22: JAIME ABADI | C22: TECNOMUNDO | D22: MSKU0540494 | E22: 46119 | F22: 46158 | G22: MSK | H22: SHANGHAI | I22: PANTACO | J22: 3100 | L22: 1700 | M22: =SUM(J22:L22) -> 4800 | N22: 0
A23: MLO-AB26021 | B23: JAIME ABADI | C23: MLO-AB | D23: CAJU5114486 | E23: 46129 | F23: 46159 | G23: MSK | H23: NINGBO | I23: LAZARO CARDENAS,MX | J23: =2950+200 -> 3150 | L23: 0 | M23: =SUM(J23:L23) -> 3150 | N23: 0
A24: MLO-AB26016 | B24: JAIME ABADI | C24: TECNOMUNDO | D24: CAAU6205753 | E24: 46122 | F24: 46160 | G24: MSK | H24: NINGBO | I24: PANTACO | J24: 3100 | L24: 1700 | M24: =SUM(J24:L24) -> 4800 | N24: 0
A25: MLO-AB26030 | B25: JAIME ABADI | C25: MLO-AB | D25: GAOU7325610 | E25: 46138 | F25: 46168 | G25: ZIM | H25: NINGBO | I25: HOUSTON | J25: 4450 | L25: 0 | M25: =SUM(J25:L25) -> 4450 | N25: 0
A26: MLO-AB26032 | B26: JAIME ABADI | C26: MLO-AB | D26: JZPU8024650 | E26: 46147 | F26: 46175 | G26: ZIM | H26: NINGBO | I26: HOUSTON | J26: 4430 | L26: 0 | M26: =SUM(J26:L26) -> 4430 | N26: 0
A27: MLO-AB26031 | B27: JAIME ABADI | C27: SALOMON | D27: ZCSU7319366 | E27: 46147 | F27: 46175 | G27: ZIM | H27: NINGBO | I27: HOUSTON | J27: 4430 | L27: 0 | M27: =SUM(J27:L27) -> 4430 | N27: 0
A28: MLO-AB26026 | B28: JAIME ABADI | C28: MLO-AB | D28: CAAU7892187 | E28: 46143 | F28: 46178 | G28: MSC | H28: NINGBO | I28: PANTACO | J28: 3100 | L28: 1850 | M28: =SUM(J28:L28) -> 4950 | N28: 0
A29: MLO-AB26028 | B29: JAIME ABADI | C29: MLO-AB | D29: MSNU5896374 | E29: 46143 | F29: 46180 | G29: MSC | H29: NINGBO | I29: PANTACO | J29: 3100 | L29: 1850 | M29: =SUM(J29:L29) -> 4950 | N29: 0
A30: MLO-AB26033 | B30: JAIME ABADI | C30: MLO-AB | D30: MSDU8916387 | E30: 46146 | F30: 46185 | G30: MSC | H30: NINGBO | I30: PANTACO | J30: 3100 | L30: 1850 | M30: =SUM(J30:L30) -> 4950 | N30: 0
A31: MLO-AB26029 | B31: JAIME ABADI | C31: MLO-AB | D31: MRKU3544552 | E31: 46150 | F31: 46188 | G31: MSK | H31: NINGBO | I31: PANTACO | J31: 3000 | L31: 1700 | M31: =SUM(J31:L31) -> 4700 | N31: 0
A32: MLO-AB26040 | B32: JAIME ABADI | C32: MLO-AB | D32: MAGU5329056 | E32: 46162 | F32: 46192 | G32: COSCO | H32: NINGBO | I32: HOUSTON | J32: 5280 | L32: 0 | M32: =SUM(J32:L32) -> 5280 | N32: 0
A33: MLO-AB26034 | B33: JAIME ABADI | C33: MLO-AB | D33: MRKU4578449 | E33: 46154 | F33: 46193 | G33: MSK | H33: SHANGHAI | I33: PANTACO | J33: 3050 | L33: 1700 | M33: =SUM(J33:L33) -> 4750 | N33: 0
A34: MLO-AB26035 | B34: JAIME ABADI | C34: MLO-AB | D34: TCKU6978502 | E34: 46154 | F34: 46193 | G34: MSK | H34: SHANGHAI | I34: PANTACO | J34: 3050 | L34: 1700 | M34: =SUM(J34:L34) -> 4750 | N34: 0
A35: MLO-AB26036 | B35: JAIME ABADI | C35: MLO-AB | D35: GAOU7171310 | E35: 46154 | F35: 46193 | G35: MSK | H35: SHANGHAI | I35: PANTACO | J35: 3050 | L35: 1700 | M35: =SUM(J35:L35) -> 4750 | N35: 0
... A40: MLO-AB26043 | B40: JAIME ABADI | C40: MLO-AB | D40: TGBU9836105 | E40: 46161 | F40: 46199 | G40: ONE | H40: NINGBO | I40: PANTACO | J40: 4350 | L40: 1700 | M40: =SUM(J40:L40) -> 6050 | N40: 0
A41: MLO-AB26044 | B41: JAIME ABADI | C41: MLO-AB | D41: NYKU0847904 | E41: 46161 | F41: 46199 | G41: ONE | H41: NINGBO | I41: PANTACO | J41: 4350 | L41: 1700 | M41: =SUM(J41:L41) -> 6050 | N41: 0 | O41: Include cancelation fee $300 & below charges $221.69 Manifest Cancellation Fee: ￥375 Manifest Fee: ￥106 Detention Fee: ￥960 & after loaded to houston, Rosalba ask take back and ship to Mexico total charges $938.77
A42: MLO-AB26048 | B42: JAIME ABADI | C42: MLO-AB | D42: CICU6783487 | E42: 46168 | F42: 46199 | G42: ZIM | H42: SHANGHAI | I42: HOUSTON | J42: 4780 | L42: 0 | M42: =SUM(J42:L42) -> 4780 | N42: 0
A43: MLO-AB26051 | B43: JAIME ABADI | C43: MLO-AB | D43: FSCU8614663 | E43: 46169 | F43: 46201 | G43: ONE | H43: NINGBO | I43: PANTACO | J43: 4500 | L43: 1700 | M43: =SUM(J43:L43) -> 6200 | N43: 0
A44: MLO-AB26052 | B44: JAIME ABADI | C44: MLO-AB | D44: TGBU5967895 | E44: 46173 | F44: 46203 | G44: ZIM | H44: NINGBO | I44: HOUSTON | J44: 4980 | L44: 0 | M44: =SUM(J44:L44) -> 4980 | N44: 0
...

Sheet NUDU
K1: =SUM(K3:K159)-SUM(N4:N20) -> 0
A2: REF/INV NO | B2: CUSTOMER | C2: CUSTOMER FOR | D2: CONTAINER | E2: ETD | F2: ETA | G2: SHIPPING LINE | H2: POL | I2: POD | J2: BILL AMT
A3: NUDU-26001/B7 | B3: NUDU | C3: NUDU | D3: CSNU6026379 | E3: 46035 | F3: 46057 | G3: COSCO | H3: QINGDAO | I3: MANZANILLO,MX | J3: 1450 | K3: have paid to ML-CHINA | M3: DATE | N3: PAY
A4: NUDU-26002/B8 | B4: NUDU | C4: NUDU | D4: DFSU7408071 | E4: 46035 | F4: 46057 | G4: COSCO | H4: QINGDAO | I4: MANZANILLO,MX | J4: 1450 | K4: have paid to ML-CHINA | M4: 46136 | N4: 10500
A5: NUDU-26003/B9 | B5: NUDU | C5: NUDU | D5: UETU5389258 | E5: 46035 | F5: 46057 | G5: COSCO | H5: QINGDAO | I5: MANZANILLO,MX | J5: 1450 | K5: have paid to ML-CHINA | M5: 46126 | N5: 7500
A6: NUDU-26004/B10 | B6: NUDU | C6: NUDU | D6: CSNU5614866 | E6: 46035 | F6: 46057 | G6: COSCO | H6: QINGDAO | I6: MANZANILLO,MX | J6: 1450 | K6: have paid to ML-CHINA | M6: 41925 | N6: 5000
A7: NUDU-26006//945 | B7: NUDU | C7: NUDU | D7: TGBU9992957 | E7: 46045 | F7: 46064 | G7: COSCO | H7: NINGBO | I7: LAZARO CARDENAS,MX | J7: 1300 | K7: 1300
A8: NUDU-26005//944 | B8: NUDU | C8: NUDU | D8: DRYU9849521 | E8: 46037 | F8: 46069 | G8: EMC | H8: NINGBO | I8: LAZARO CARDENAS,MX | J8: 1350 | K8: 1350
A9: NUDU-26009//941 | B9: NUDU | C9: NUDU | D9: CMAU9829830 | E9: 46049 | F9: 46074 | G9: CMA | H9: TIANJIN | I9: MANZANILLO,MX | J9: 1200 | K9: 1200
A10: NUDU-26011//B11 | B10: NUDU | C10: NUDU | D10: MRSU6705170 | E10: 46053 | F10: 46081 | G10: MSK | H10: QINGDAO | I10: MANZANILLO,MX | J10: 1300 | K10: have paid to ML-CHINA
A11: NUDU-26012//B12 | B11: NUDU | C11: NUDU | D11: MRSU9488551 | E11: 46053 | F11: 46081 | G11: MSK | H11: QINGDAO | I11: MANZANILLO,MX | J11: 1300 | K11: have paid to ML-CHINA
A12: NUDU-26010//947 | B12: NUDU | C12: NUDU | D12: TEMU7860550 | E12: 46056 | F12: 46082 | G12: COSCO | H12: NINGBO | I12: LAZARO CARDENAS,MX | J12: 1400 | K12: 1400
A13: NUDU-26024//942 | B13: NUDU | C13: NUDU | D13: BSIU9686619 | E13: 46063 | F13: 46082 | G13: ZIM | H13: SHANGHAI | I13: MANZANILLO,MX | J13: 1250 | K13: 1250
A14: NUDU-26025//940 | B14: NUDU | C14: NUDU | D14: MAGU5524670 | E14: 46047 | F14: 46085 | G14: COSCO | H14: TIANJIN | I14: MANZANILLO,MX | J14: 1300 | K14: 1300
A15: NUDU-26017//B17 | B15: NUDU | C15: NUDU | D15: BEAU4267055 | E15: 46061 | F15: 46089 | G15: MSC | H15: QINGDAO | I15: MANZANILLO,MX | J15: 1300 | K15: have paid to ML-CHINA
A16: NUDU-26018//B18 | B16: NUDU | C16: NUDU | D16: TLLU8731733 | E16: 46061 | F16: 46089 | G16: MSC | H16: QINGDAO | I16: MANZANILLO,MX | J16: 1300 | K16: have paid to ML-CHINA
A17: NUDU-26019//B19 | B17: NUDU | C17: NUDU | D17: MSDU8207720 | E17: 46061 | F17: 46089 | G17: MSC | H17: QINGDAO | I17: MANZANILLO,MX | J17: 1300 | K17: have paid to ML-CHINA
A18: NUDU-26020//B20 | B18: NUDU | C18: NUDU | D18: FSCU8028560 | E18: 46061 | F18: 46089 | G18: MSC | H18: QINGDAO | I18: MANZANILLO,MX | J18: 1300 | K18: have paid to ML-CHINA
A19: NUDU-26021//B21 | B19: NUDU | C19: NUDU | D19: MSMU4159722 | E19: 46061 | F19: 46089 | G19: MSC | H19: QINGDAO | I19: MANZANILLO,MX | J19: 1300 | K19: have paid to ML-CHINA
A20: NUDU-26022//B22 | B20: NUDU | C20: NUDU | D20: TCLU1711207 | E20: 46061 | F20: 46089 | G20: MSC | H20: QINGDAO | I20: MANZANILLO,MX | J20: 1300 | K20: have paid to ML-CHINA
A21: NUDU-26023//955 | B21: NUDU | C21: NUDU | D21: ZCSU7728385 | E21: 46061 | F21: 46089 | G21: ZIM | H21: NINGBO | I21: MANZANILLO,MX | J21: 1250 | K21: 1250
A22: NUDU-26027//952 | B22: NUDU | C22: NUDU | D22: MSDU6210067 | E22: 46068 | F22: 46089 | G22: MSC | H22: NINGBO | I22: MANZANILLO,MX | J22: 2600 | K22: 2600
A23: NUDU-26029//954 | B23: NUDU | C23: NUDU | D23: MSMU4143475 | E23: 46068 | F23: 46089 | G23: MSC | H23: NINGBO | I23: MANZANILLO,MX | J23: 2600 | K23: 2600
A24: NUDU-26013//B13 | B24: NUDU | C24: NUDU | D24: CAAU6671406 | E24: 46060 | F24: 46095 | G24: MSK | H24: QINGDAO | I24: MANZANILLO,MX | J24: 1300 | K24: have paid to ML-CHINA
A25: NUDU-26014//B14 | B25: NUDU | C25: NUDU | D25: MRSU3681882 | E25: 46060 | F25: 46095 | G25: MSK | H25: QINGDAO | I25: MANZANILLO,MX | J25: 1300 | K25: have paid to ML-CHINA
A26: NUDU-26015//B15 | B26: NUDU | C26: NUDU | D26: SEGU4747143 | E26: 46060 | F26: 46095 | G26: MSK | H26: QINGDAO | I26: MANZANILLO,MX | J26: 1300 | K26: have paid to ML-CHINA
A27: NUDU-26016//B16 | B27: NUDU | C27: NUDU | D27: CAJU5187040 | E27: 46060 | F27: 46095 | G27: MSK | H27: QINGDAO | I27: MANZANILLO,MX | J27: 1300 | K27: have paid to ML-CHINA
A28: NUDU-26026//951 | B28: NUDU | C28: NUDU | D28: ZCSU7274410 | E28: 46061 | F28: 46109 | G28: CMA | H28: NINGBO | I28: HOUSTON | J28: 3400 | K28: 3400
A29: NUDU-26028//953 | B29: NUDU | C29: NUDU | D29: HMMU4368388 | E29: 46068 | F29: 46114 | G29: HMM | H29: NINGBO | I29: MANZANILLO,MX | J29: 2450 | K29: 2450
A30: NUDU-26007/B24 | B30: NUDU | C30: NUDU | D30: TRHU5820110 | E30: 46066 | F30: 46116 | G30: COSCO | H30: TIANJIN | I30: MANZANILLO,MX | J30: 1450 | K30: 1450
A31: NUDU-26008/B23 | B31: NUDU | C31: NUDU | D31: OOCU8979468 | E31: 46066 | F31: 46116 | G31: COSCO | H31: TIANJIN | I31: MANZANILLO,MX | J31: 1450 | K31: 1450

Sheet IHE
N1: =SUM(N3:N116)-SUM(Q4:Q14) -> 12650
A2: REF/INV NO | B2: CUSTOMER | C2: CUSTOMER FOR | D2: BL | E2: CONTAINER | F2: ETD | G2: ETA | H2: SHIPPING LINE | I2: POL | J2: POD | K2: TOTAL COST | L2: PREVIO/INSURANCE | M2: RAIL | N2: BILL AMT
A3: IHE-25045 | B3: ISAAC HEMZANI | C3: IHE | D3: TLX | E3: HMMU6395166 | F3: 45668 | G3: 46056 | H3: HMM | I3: NINGBO | J3: LAZARO CARDENAS,MX | K3: 1500 | L3: 0 | M3: 0 | N3: =K3+L3 -> 1500 | P3: DATE | Q3: PAY
A4: IHE-26001 | B4: ISAAC HEMZANI | C4: IHE | D4: TLX | E4: HMMU7115830 | F4: 46054 | G4: 46077 | H4: HMM | I4: NINGBO | J4: LAZARO CARDENAS,MX | K4: 1550 | L4: 0 | M4: 0 | N4: =K4+L4 -> 1550 | P4: 46112 | Q4: 6500
A5: IHE-26003 | B5: ISAAC HEMZANI | C5: IHE | D5: TLX | E5: HMMU4747777 | F5: 46054 | G5: 46077 | H5: HMM | I5: NINGBO | J5: LAZARO CARDENAS,MX | K5: 1550 | L5: 0 | M5: 0 | N5: =K5+L5 -> 1550 | P5: 46185 | Q5: 20000
A6: IHEMSANI-26001 | B6: ISAAC HEMZANI | C6: IHE | D6: TLX | E6: TGBU7755792 | F6: 46051 | G6: 46082 | H6: CMA | I6: NINGBO | J6: HOUSTON , TEXAS, US | K6: 3750 | L6: 0 | M6: 0 | N6: =K6+L6 -> 3750 | P6: 46212 | Q6: 20000
A7: IHEMSANI-26002 | B7: ISAAC HEMZANI | C7: IHE | D7: TLX | E7: SEGU4416079 | F7: 46051 | G7: 46082 | H7: CMA | I7: NINGBO | J7: HOUSTON , TEXAS, US | K7: 3750 | L7: 0 | M7: 0 | N7: =K7+L7 -> 3750 | P7: 46227 | Q7: 8200
A8: IHE-26005 | B8: ISAAC HEMSANI | C8: IHE | D8: TLX | E8: OOCU8228169 | F8: 46054 | G8: 46082 | H8: COSCO | I8: NINGBO | J8: LAZARO CARDENAS,MX | K8: 1600 | L8: 0 | M8: 0 | N8: =K8+L8 -> 1600 | P8: 46247 | Q8: 6250
A9: IHE-26004 | B9: ISAAC HEMZANI | C9: IHE | D9: TLX | E9: TCNU5552564 | F9: 46047 | G9: 46089 | H9: COSCO | I9: TIANJIN | J9: LAZARO CARDENAS,MX | K9: 1500 | L9: 0 | M9: 0 | N9: =K9+L9 -> 1500 | P9: 46289 | Q9: 10000
A10: IHEMSANI-26003 | B10: ISAAC HEMZANI | C10: IHE | D10: TLX | E10: CSNU5678963 | F10: 46065 | G10: 46092 | H10: COSCO | I10: NINGBO | J10: HOUSTON | K10: 3550 | L10: 0 | M10: 0 | N10: =K10+L10 -> 3550 | P10: 46308 | Q10: 10000
A11: IHEMSANI-26004 | B11: ISAAC HEMZANI | C11: IHE | D11: TLX | E11: CSNU6946947 | F11: 46065 | G11: 46092 | H11: COSCO | I11: NINGBO | J11: HOUSTON | K11: 3550 | L11: 0 | M11: 0 | N11: =K11+L11 -> 3550
A12: IHE-26008 | B12: ISAAC HEMZANI | C12: IHE | D12: TLX | E12: OOLU9197599 | F12: 46066 | G12: 46101 | H12: COSCO | I12: TIANJIN | J12: LAZARO CARDENAS,MX | K12: 1450 | L12: 0 | M12: 0 | N12: =K12+L12 -> 1450
A13: IHE-26007 | B13: ISAAC HEMZANI | C13: IHE | D13: TLX | E13: EGSU9369167 | F13: 46086 | G13: 46106 | H13: EMC | I13: NINGBO | J13: LAZARO CARDENAS,MX | K13: 3000 | L13: 0 | M13: 0 | N13: 2950
A14: IHE-26006 | B14: ISAAC HEMZANI | C14: IHE | D14: TLX | E14: TRHU7960574 | F14: 46086 | G14: 46106 | H14: EMC | I14: NINGBO | J14: LAZARO CARDENAS,MX | K14: 3100 | L14: 0 | M14: 0 | N14: =K14+L14 -> 3100
A15: IHE-26002 | B15: ISAAC HEMZANI | C15: IHE | D15: TLX | E15: HMMU4731560 | F15: 46068 | G15: 46112 | H15: HMM | I15: NINGBO | J15: LAZARO CARDENAS,MX | K15: 2550 | L15: 0 | M15: 0 | N15: =K15+L15 -> 2550
A16: IHE-26009 | B16: ISAAC HEMZANI | C16: IHE | D16: TLX | E16: TXGU7206706 | F16: 46105 | G16: 46130 | H16: CMA | I16: TIANJIN | J16: MANZANILLO | K16: 3150 | L16: 0 | M16: 0 | N16: =K16+L16 -> 3150
A17: IHE-26010 | B17: ISAAC HEMZANI | C17: IHE | D17: TLX | E17: CSNU7289786 | F17: 46105 | G17: 46131 | H17: COSCO | I17: NINGBO | J17: LAZARO CARDENAS,MX | K17: 2900 | L17: 0 | M17: 0 | N17: =K17+L17 -> 2900
A18: IHE-26012 | B18: ISAAC HEMZANI | C18: IHE | D18: TLX | E18: DFSU7360363 | F18: 46119 | G18: 46144 | H18: CMA | I18: TIANJIN | J18: MANZANILLO | K18: 3150 | L18: 0 | M18: 0 | N18: =K18+L18 -> 3150
A19: IHE-26011 | B19: ISAAC HEMZANI | C19: IHE | D19: TLX | E19: CMAU9884843 | F19: 46119 | G19: 46148 | H19: CMA | I19: TIANJIN | J19: LAZARO CARDENAS,MX | K19: 3150 | L19: 0 | M19: 0 | N19: =K19+L19 -> 3150
A20: IHE-26013 | B20: ISAAC HEMZANI | C20: IHE | D20: TLX | E20: APHU6793680 | F20: 46147 | G20: 46178 | H20: CMA | I20: TIANJIN | J20: LAZARO CARDENAS,MX | K20: 3050 | L20: 0 | M20: 0 | N20: =K20+L20 -> 3050
A21: IHE-26014 | B21: ISAAC HEMZANI | C21: IHE | D21: TLX | E21: CMAU4207161 | F21: 46180 | G21: 46211 | H21: CMA | I21: TIANJIN | J21: LAZARO CARDENAS,MX | K21: 5350 | L21: 0 | M21: 0 | N21: =K21+L21 -> 5350
A22: IHE-26015 | B22: ISAAC HEMZANI | C22: IHE | D22: TLX | E22: MRSU4798024 | F22: 46188 | G22: 46218 | H22: MSK | I22: TIANJIN | J22: LAZARO CARDENAS,MX | K22: 6250 | L22: 0 | M22: 0 | N22: =K22+L22 -> 6250
A23: IHE-26016 | B23: ISAAC HEMZANI | C23: IHE | D23: TLX | E23: OOCU7988362 | F23: 46189 | G23: 46215 | H23: COSCO | I23: NINGBO | J23: LAZARO CARDENAS,RAIL-PANTACO(MEXICO CITY) | K23: 8200 | L23: 0 | M23: 0 | N23: =K23+L23 -> 8200
A24: IHE-26017 | B24: ISAAC HEMZANI | C24: IHE | D24: TLX | E24: FFAU3367862 | F24: 46221 | G24: 46249 | H24: COSCO | I24: QINGDAO | J24: LAZARO CARDENAS,MX | K24: 5500 | L24: 0 | M24: 0 | N24: =K24+L24 -> 5500
A25: IHE-26018 | B25: ISAAC HEMZANI | C25: IHE | D25: TLX | E25: SEGU6838258 | F25: 46224 | G25: 46264 | H25: COSCO | I25: NINGBO | J25: LAZARO CARDENAS,MX | K25: 5500 | L25: 0 | M25: 0 | N25: =K25+L25 -> 5500
A26: IHE-26019 | B26: ISAAC HEMZANI | C26: IHE | D26: TLX | E26: UETU5469477 | F26: 46238 | G26: 46276 | H26: COSCO | I26: NINGBO | J26: LAZARO CARDENAS,MX | K26: 5400 | L26: 0 | M26: 0 | N26: =K26+L26 -> 5400
A27: IHE-26021 | B27: ISAAC HEMZANI | C27: IHE | D27: TLX | E27: TCKU7219305 | F27: 46273 | G27: 46295 | H27: ONE | I27: NINGBO | J27: PANTACO | K27: 7950 | L27: 0 | M27: 1700 | N27: =K27+L27+M27 -> 9650

Sheet ELI
L1: =SUM(L3:L54) -> 0
A2: REF/INV NO | B2: CUSTOMER | C2: CUSTOMER FOR | D2: BL | E2: CONTAINER | F2: ETD | G2: ETA | H2: SHIPPING LINE | I2: POL | J2: POD | K2: BILL AMT
N3: DATE | O3: PAY

Sheet HHB
N1: =SUM(M3:M124)-SUM(Q4:Q124) -> 19337
A2: REF/INV NO | B2: CUSTOMER | C2: CUSTOMER FOR | D2: BL | E2: CONTAINER | F2: ETD | G2: ETA | H2: SHIPPING LINE | I2: POL | J2: POD | K2: TOTAL COST | L2: EXW FEE | M2: BILL AMT
A3: HHB-26001 | B3: HABIB HASBANI | C3: MLO-HHB | D3: TLX | E3: SKIU9100097 | F3: 46042 | G3: 46064 | H3: EMC | I3: SHENZHEN | J3: LAZARO CARDENAS,MX | K3: 1350 | L3: 0 | M3: =K3+L3 -> 1350 | N3: 0 | P3: DATE | Q3: PAY
A4: HHB-26002 | B4: HABIB HASBANI | C4: MLO-HHB | D4: TLX | E4: SEKU5891041 | F4: 46049 | G4: 46077 | H4: CMA | I4: TIANJIN | J4: LAZARO CARDENAS,MX | K4: 1150 | L4: 0 | M4: =K4 -> 1150 | N4: 0 | P4: 46128 | Q4: 12250
A5: HHB-26003 | B5: HABIB HASBANI | C5: MLO-HHB | D5: TLX | E5: MSDU6194177 | F5: 46050 | G5: 46084 | H5: MSC | I5: XIAMEN | J5: LAZARO CARDENAS,MX | K5: 1330 | L5: 1150 | M5: 2500 | N5: 0 | P5: 46254 | Q5: 19963
A6: HHB-26004 | B6: HABIB HASBANI | C6: MLO-HHB | D6: TLX | E6: MSMU7576247 | F6: 46057 | G6: 46091 | H6: MSC | I6: XIAMEN | J6: LAZARO CARDENAS,MX | K6: 1330 | L6: 1150 | M6: 2500 | N6: 0
A7: HHB-26005 | B7: HABIB HASBANI | C7: MLO-HHB | D7: TLX | E7: MSMU4428441 | F7: 46106 | G7: 46140 | H7: MSC | I7: XIAMEN | J7: LAZARO CARDENAS,MX | K7: 3600 | L7: 1150 | M7: =SUM(K7:L7) -> 4750 | N7: 0
A8: HHB-26006 | B8: HABIB HASBANI | C8: MLO-HHB | D8: TLX | E8: ONEU6065704 | F8: 46162 | G8: 46196 | H8: ONE | I8: XIAMEN | J8: LAZARO CARDENAS,MX | K8: 4150 | L8: 1150 | M8: =SUM(K8:L8) -> 5300 | N8: 0
A9: HHB-26007 | B9: HABIB HASBANI | C9: MLO-HHB | D9: TLX | E9: BMOU6476444 | F9: 46173 | G9: 46206 | H9: CMA | I9: NINGBO | J9: LAZARO CARDENAS,MX | K9: 5350 | L9: 0 | M9: =SUM(K9:L9) -> 5350 | N9: 0
A10: HHB-26009 | B10: HABIB HASBANI | C10: MLO-HHB | D10: TLX | E10: MSDU5291510 | F10: 46183 | G10: 46217 | H10: MSC | I10: XIAMEN | J10: LAZARO CARDENAS,MX | K10: 6300 | L10: 1150 | M10: =SUM(K10:L10) -> 7450 | N10: 0
A11: HHB-26008 | B11: HABIB HASBANI | C11: MLO-HHB | D11: TLX | E11: MSMU7948386 | F11: 46183 | G11: 46218 | H11: MSC | I11: SHENZHEN | J11: LAZARO CARDENAS,MX | K11: 6250 | L11: 0 | M11: =SUM(K11:L11) -> 6250 | N11: 4386.95
A12: HHB-26010 | B12: HABIB HASBANI | C12: MLO-HHB | D12: TLX | E12: CAAU4534132 | F12: 46259 | G12: 46291 | H12: MSK | I12: NINGBO | J12: LAZARO CARDENAS,MX | K12: 7600 | L12: 0 | M12: =SUM(K12:L12) -> 7600 | N12: =SUM(L12:M12) -> 7600
A13: HHB-26011 | B13: HABIB HASBANI | C13: MLO-HHB | D13: TLX | E13: MSBU8306176 | F13: 46255 | G13: 46289 | H13: MSC | I13: TIANJIN | J13: LAZARO CARDENAS,MX | K13: 7350 | L13: 0 | M13: =SUM(K13:L13) -> 7350 | N13: =SUM(L13:M13) -> 7350

Sheet RED
P1: =SUM(O3:O118)-SUM(S4:S5) -> 40680
A2: REF/INV NO | B2: CUSTOMER | C2: CUSTOMER FOR | D2: BL | E2: CONTAINER | F2: ETD | G2: ETA | H2: SHIPPING LINE | I2: POL | J2: POD | K2: TOTAL COST | L2: RAIL | M2: PREVIO | N2: INSURANCE | O2: BILL AMT
A3: RED-26001 | B3: SHLOMO GALOR | C3: SHLOMO GALOR | D3: TLX | E3: TRHU6545840 | F3: 46040 | G3: 46064 | H3: EMC | I3: SHENZHEN | J3: LAZARO CARDENAS,MX | K3: 1350 | L3: 0 | M3: 180 | N3: 100 | O3: =SUM(K3:N3) -> 1630 | P3: 0 | R3: DATE | S3: PAY
A4: RED-26002 | B4: SHLOMO GALOR | C4: SHLOMO GALOR | D4: TLX | E4: TCNU4831461 | F4: 46043 | G4: 46080 | H4: ONE | I4: YANTIAN | J4: LAZARO CARDENAS,MX | K4: 1250 | L4: 0 | M4: 180 | N4: 100 | O4: =SUM(K4:N4) -> 1530 | P4: 0 | R4: 46301 | S4: 40000
A5: RED-26003 | B5: SHLOMO GALOR | C5: SHLOMO GALOR | D5: TLX | E5: EGSU1742058 | F5: 46054 | G5: 46085 | H5: EMC | I5: SHEKOU | J5: LAZARO CARDENAS,MX | K5: 1450 | L5: 0 | M5: 180 | N5: 100 | O5: =SUM(K5:N5) -> 1730 | P5: 0
A6: RED-26004 | B6: SHLOMO GALOR | C6: SHLOMO GALOR | D6: TLX | E6: MSDU8637905 | F6: 46059 | G6: 46098 | H6: MSC | I6: SHEKOU | J6: LAZARO CARDENAS,MX | K6: 1350 | L6: 0 | M6: 180 | N6: 100 | O6: =SUM(K6:N6) -> 1630 | P6: 0
A7: RED-26005 | B7: SHLOMO GALOR | C7: SHLOMO GALOR | D7: TLX | E7: TCLU4980508 | F7: 46066 | G7: 46098 | H7: MSC | I7: SHEKOU | J7: LAZARO CARDENAS,MX | K7: 2600 | L7: 0 | M7: 180 | N7: 100 | O7: =SUM(K7:N7) -> 2880 | P7: 0
A8: RED-26006 | B8: SHLOMO GALOR | C8: SHLOMO GALOR | D8: TLX | E8: MSMU8563012 | F8: 46106 | G8: 46140 | H8: MSC | I8: XIAMEN | J8: LAZARO CARDENAS,MX | K8: 3500 | L8: 0 | M8: 180 | N8: 100 | O8: =SUM(K8:N8) -> 3780 | P8: 0
A9: RED-26007 | B9: SHLOMO GALOR | C9: SHLOMO GALOR | D9: TLX | E9: EMCU1726823 | F9: 46110 | G9: 46134 | H9: EMC | I9: SHEKOU | J9: LAZARO CARDENAS,MX | K9: 3150 | L9: 0 | M9: 180 | N9: 100 | O9: =SUM(K9:N9) -> 3430 | P9: 0
A10: RED-26008 | B10: SHLOMO GALOR | C10: SHLOMO GALOR | D10: TLX | E10: CAIU7768374 | F10: 46134 | G10: 46166 | H10: MSC | I10: YANTIAN | J10: LAZARO CARDENAS,RAIL-PANTACO(MEXICO CITY) | K10: 3100 | L10: 1700 | M10: 180 | N10: 100 | O10: =SUM(K10:N10) -> 5080 | P10: 0
A11: RED-26009 | B11: SHLOMO GALOR | C11: SHLOMO GALOR | D11: TLX | E11: TGBU6439824 | F11: 46148 | G11: 46180 | H11: MSC | I11: YANTIAN | J11: LAZARO CARDENAS,RAIL-PANTACO(MEXICO CITY) | K11: 3100 | L11: 1850 | M11: 180 | N11: 100 | O11: =SUM(K11:N11) -> 5230 | P11: 0
A12: RED-26010 | B12: SHLOMO GALOR | C12: SHLOMO GALOR | D12: TLX | E12: TCNU7624581 | F12: 46148 | G12: 46182 | H12: MSC | I12: XIAMEN | J12: LAZARO CARDENAS,RAIL-PANTACO(MEXICO CITY) | K12: 3100 | L12: 1850 | M12: 180 | N12: 100 | O12: =SUM(K12:N12) -> 5230 | P12: 0
A13: RED-26011 | B13: SHLOMO GALOR | C13: SHLOMO GALOR | D13: TLX | E13: ONEU6396003 | F13: 46183 | G13: 46224 | H13: ONE | I13: XIAMEN | J13: LAZARO CARDENAS,RAIL-PANTACO(MEXICO CITY) | K13: 6200 | L13: 1850 | M13: 180 | N13: 100 | O13: =SUM(K13:N13) -> 8330 | P13: 580
A14: RED-26012 | B14: SHLOMO GALOR | C14: SHLOMO GALOR | D14: TLX | E14: MSMU7260449 | F14: 46210 | G14: 46248 | H14: MSC | I14: XIAMEN | J14: LAZARO CARDENAS,RAIL-PANTACO(MEXICO CITY) | K14: 5900 | L14: 1850 | M14: 180 | N14: 100 | O14: =SUM(K14:N14) -> 8030 | P14: =O14 -> 8030
A15: RED-26013 | B15: SHLOMO GALOR | C15: SHLOMO GALOR | D15: TLX | E15: ONEU4694354 | F15: 46218 | G15: 46252 | H15: ONE | I15: XIAMEN | J15: LAZARO CARDENAS,RAIL-PANTACO(MEXICO CITY) | K15: 5200 | L15: 1850 | M15: 180 | N15: 100 | O15: =SUM(K15:N15) -> 7330 | P15: =O15 -> 7330
A16: RED-26014 | B16: SHLOMO GALOR | C16: SHLOMO GALOR | D16: TLX | E16: ONEU4706223 | F16: 46232 | G16: 46266 | H16: ONE | I16: XIAMEN | J16: LAZARO CARDENAS,RAIL-PANTACO(MEXICO CITY) | K16: 4700 | L16: 1700 | M16: 180 | N16: 100 | O16: =SUM(K16:N16) -> 6680 | P16: =O16 -> 6680
A17: RED-26015 | B17: SHLOMO GALOR | C17: SHLOMO GALOR | D17: TLX | E17: ONEU4706178 | F17: 46246 | G17: 46283 | H17: ONE | I17: XIAMEN | J17: LAZARO CARDENAS,RAIL-PANTACO(MEXICO CITY) | K17: 6600 | L17: 1700 | M17: 180 | N17: 100 | O17: =SUM(K17:N17) -> 8580 | P17: =O17 -> 8580
A18: RED-26016 | B18: SHLOMO GALOR | C18: SHLOMO GALOR | D18: TLX | E18: TCNU6892846 | F18: 46281 | G18: 46326 | H18: ONE | I18: XIAMEN | J18: LAZARO CARDENAS,RAIL-PANTACO(MEXICO CITY) | K18: 7600 | L18: 1700 | M18: 180 | N18: 100 | O18: =SUM(K18:N18) -> 9580 | P18: =O18 -> 9580

Sheet MAN
O1: =SUM(O3:O227)-SUM(R3:R20) -> 50110.91
A2: REF/INV NO | B2: CUSTOMER | C2: CUSTOMER FOR | D2: BL | E2: CONTAINER | F2: ETD | G2: ETA | H2: SHIPPING LINE | I2: POL | J2: POD | K2: TOTAL COST | L2: RAIL | M2: PREVIO | N2: INSURANCE | O2: BILL AMT | Q2: DATE | R2: PAY
A3: MAN-26001 | B3: DAVID MANN | C3: DAVID MANN | D3: TLX | E3: EMCU8556797 | F3: 46033 | G3: 46059 | H3: EMC | I3: SHEKOU | J3: LAZARO CARDENAS,RAIL-PANTACO(MEXICO CITY) | K3: 1700 | L3: 1600 | M3: 180 | N3: 100 | O3: =SUM(K3:N3) -> 3580 | R3: 15000
A4: MAN-26002 | B4: DAVID MANN | C4: DAVID MANN | D4: TLX | E4: EGSU6100301 | F4: 46032 | G4: 46060 | H4: EMC | I4: SHANGHAI | J4: LAZARO CARDENAS,RAIL-PANTACO(MEXICO CITY) | K4: 1700 | L4: 1600 | M4: 180 | N4: 100 | O4: =SUM(K4:N4) -> 3580 | Q4: 46126 | R4: 421
A5: MAN-25071 | B5: DAVID MANN | C5: DAVID MANN | D5: TLX | E5: ONEU5419547 | F5: 45671 | G5: 46071 | H5: ONE | I5: XIAMEN | J5: LAZARO CARDENAS,MX | K5: 1300 | L5: 0 | M5: 180 | N5: 100 | O5: =SUM(K5:N5) -> 1580 | Q5: 46132 | R5: 19016
A6: MAN-25072 | B6: DAVID MANN | C6: DAVID MANN | D6: TLX | E6: TGBU4611908 | F6: 45671 | G6: 46077 | H6: ONE | I6: XIAMEN | J6: LAZARO CARDENAS,MX | K6: 1300 | L6: 0 | M6: 180 | N6: 100 | O6: =SUM(K6:N6) -> 1580 | Q6: 46205 | R6: 27030
A7: MAN-25073 | B7: DAVID MANN | C7: DAVID MANN | D7: TLX | E7: TRHU5579872 | F7: 45671 | G7: 46077 | H7: ONE | I7: XIAMEN | J7: LAZARO CARDENAS,MX | K7: 1300 | L7: 0 | M7: 180 | N7: 100 | O7: =SUM(K7:N7) -> 1580 | Q7: 46258 | R7: 20591.07
A8: MAN-25074 | B8: DAVID MANN | C8: DAVID MANN | D8: TLX | E8: NYKU4975420 | F8: 45671 | G8: 46077 | H8: ONE | I8: XIAMEN | J8: LAZARO CARDENAS,RAIL-PANTACO(MEXICO CITY) | K8: 1300 | L8: 1600 | M8: 180 | N8: 100 | O8: =SUM(K8:N8) -> 3180 | Q8: 46289 | R8: 21937.02
A9: MAN-25075 | B9: DAVID MANN | C9: DAVID MANN | D9: TLX | E9: FFAU6678317 | F9: 45671 | G9: 46077 | H9: ONE | I9: XIAMEN | J9: LAZARO CARDENAS,RAIL-PANTACO(MEXICO CITY) | K9: 1300 | L9: 1600 | M9: 180 | N9: 100 | O9: =SUM(K9:N9) -> 3180 | Q9: 46311 | R9: 29014
A10: MAN-26003 | B10: DAVID MANN | C10: DAVID MANN | D10: TLX | E10: FFAU6298739 | F10: 46036 | G10: 46077 | H10: ONE | I10: XIAMEN | J10: LAZARO CARDENAS,RAIL-PANTACO(MEXICO CITY) | K10: 1300 | L10: 1600 | M10: 180 | N10: 100 | O10: =SUM(K10:N10) -> 3180
A11: MAN-26004 | B11: DAVID MANN | C11: DAVID MANN | D11: TLX | E11: MEDU7453552 | F11: 46050 | G11: 46084 | H11: MSC | I11: XIAMEN | J11: LAZARO CARDENAS,MX | K11: 1350 | L11: 0 | M11: 180 | N11: 100 | O11: =SUM(K11:N11) -> 1630
A12: MAN-26005 | B12: DAVID MANN | C12: DAVID MANN | D12: TLX | E12: MSNU5060867 | F12: 46050 | G12: 46084 | H12: MSC | I12: XIAMEN | J12: LAZARO CARDENAS,RAIL-PANTACO(MEXICO CITY) | K12: 1350 | L12: 1570 | M12: 180 | N12: 100 | O12: =SUM(K12:N12) -> 3200
A13: MAN-26006 | B13: DAVID MANN | C13: DAVID MANN | D13: TLX | E13: MSMU6363606 | F13: 46057 | G13: 46091 | H13: MSC | I13: XIAMEN | J13: LAZARO CARDENAS,MX | K13: 1350 | L13: 0 | M13: 180 | N13: 100 | O13: =SUM(K13:N13) -> 1630
A14: MAN-26008 | B14: DAVID MANN | C14: DAVID MANN | D14: TLX | E14: GAOU7885662 | F14: 46057 | G14: 46091 | H14: MSC | I14: XIAMEN | J14: LAZARO CARDENAS,RAIL-PANTACO(MEXICO CITY) | K14: 1350 | L14: 1570 | M14: 0 | N14: 100 | O14: =SUM(K14:N14) -> 3020
A15: MAN-26007 | B15: DAVID MANN | C15: DAVID MANN | D15: TLX | E15: MSMU4309294 | F15: 46064 | G15: 46095 | H15: MSC | I15: SHANGHAI | J15: LAZARO CARDENAS,RAIL-PANTACO(MEXICO CITY) | K15: 1350 | L15: 1570 | M15: 180 | N15: 100 | O15: =SUM(K15:N15) -> 3200
A16: MAN-26009 | B16: DAVID MANN | C16: DAVID MANN | D16: TLX | E16: TCLU9105736 | F16: 46064 | G16: 46098 | H16: MSC | I16: XIAMEN | J16: LAZARO CARDENAS,RAIL-PANTACO(MEXICO CITY) | K16: 1350 | L16: 1570 | M16: 180 | N16: 100 | O16: =SUM(K16:N16) -> 3200
A17: MAN-26010 | B17: DAVID MANN | C17: DAVID MANN | D17: TLX | E17: BEAU4270254 | F17: 46071 | G17: 46105 | H17: MSC | I17: XIAMEN | J17: LAZARO CARDENAS,MX | K17: 2600 | L17: 0 | M17: 180 | N17: 100 | O17: =SUM(K17:N17) -> 2880
A18: MAN-26011 | B18: DAVID MANN | C18: DAVID MANN | D18: TLX | E18: MSDU6814093 | F18: 46092 | G18: 46126 | H18: MSC | I18: XIAMEN | J18: LAZARO CARDENAS,MX | K18: 3400 | L18: 0 | M18: 180 | N18: 100 | O18: =SUM(K18:N18) -> 3680
A19: MAN-26012 | B19: DAVID MANN | C19: DAVID MANN | D19: TLX | E19: MSMU5832680 | F19: 46099 | G19: 46133 | H19: MSC | I19: XIAMEN | J19: LAZARO CARDENAS,MX | K19: 3050 | L19: 0 | M19: 180 | N19: 100 | O19: =SUM(K19:N19) -> 3330
A20: MAN-26014 | B20: DAVID MANN | C20: DAVID MANN | D20: TLX | E20: MSCU5258099 | F20: 46120 | G20: 46154 | H20: MSC | I20: XIAMEN | J20: LAZARO CARDENAS,MX | K20: 3200 | L20: 0 | M20: 180 | N20: 100 | O20: =SUM(K20:N20) -> 3480
A21: MAN-26013 | B21: DAVID MANN | C21: DAVID MANN | D21: TLX | E21: MEDU4348229 | F21: 46114 | G21: 46155 | H21: MSC | I21: XIAMEN | J21: LAZARO CARDENAS,RAIL-PANTACO(MEXICO CITY) | K21: 3250 | L21: 1570 | M21: 180 | N21: 100 | O21: =SUM(K21:N21) -> 5100
... A39: MAN-26031 | B39: DAVID MANN | C39: DAVID MANN | D39: TLX | E39: CSGU6534961 | F39: 46235 | G39: 46273 | H39: COSCO | I39: SHANGHAI | J39: LAZARO CARDENAS,MX | K39: 5600 | L39: 0 | M39: 180 | N39: 100 | O39: =SUM(K39:N39) -> 5880
A40: MAN-26032 | B40: DAVID MANN | C40: DAVID MANN | D40: TLX | E40: FFAU6723946 | F40: 46239 | G40: 46277 | H40: ONE | I40: XIAMEN | J40: LAZARO CARDENAS,MX | K40: =5600+40 -> 5640 | L40: 0 | M40: 180 | N40: 100 | O40: =SUM(K40:N40) -> 5920
A41: MAN-26033 | B41: DAVID MANN | C41: DAVID MANN | D41: TLX | E41: TEMU7081993 | F41: 46239 | G41: 46277 | H41: ONE | I41: XIAMEN | J41: LAZARO CARDENAS,MX | K41: =5600+40 -> 5640 | L41: 0 | M41: 180 | N41: 100 | O41: =SUM(K41:N41) -> 5920
A42: MAN-26034 | B42: DAVID MANN | C42: DAVID MANN | D42: TLX | E42: SEKU4396341 | F42: 46239 | G42: 46277 | H42: ONE | I42: XIAMEN | J42: LAZARO CARDENAS,MX | K42: =5600+40 -> 5640 | L42: 0 | M42: 180 | N42: 100 | O42: =SUM(K42:N42) -> 5920
A43: MAN-26035 | B43: DAVID MANN | C43: DAVID MANN | D43: TLX | E43: TCNU4002877 | F43: 46239 | G43: 46277 | H43: ONE | I43: XIAMEN | J43: LAZARO CARDENAS,MX | K43: =5600+40 -> 5640 | L43: 0 | M43: 180 | N43: 100 | O43: =SUM(K43:N43) -> 5920
A44: MAN-26036 | B44: DAVID MANN | C44: DAVID MANN | D44: TLX | E44: ONEU1951778 | F44: 46239 | G44: 46277 | H44: ONE | I44: XIAMEN | J44: LAZARO CARDENAS,MX | K44: =5600+40 -> 5640 | L44: 0 | M44: 180 | N44: 100 | O44: =SUM(K44:N44) -> 5920
A45: MAN-26039 | B45: DAVID MANN | C45: DAVID MANN | D45: TLX | E45: TIIU5974830 | F45: 46250 | G45: 46287 | H45: ONE | I45: SHANGHAI | J45: LAZARO CARDENAS,MX | K45: 7400 | L45: 0 | M45: 180 | N45: 100 | O45: =SUM(K45:N45) -> 7680
A46: MAN-26038 | B46: DAVID MANN | C46: DAVID MANN | D46: TLX | E46: FFAU3036294 | F46: 46269 | G46: 46294 | H46: COSCO | I46: SHANGHAI | J46: LAZARO CARDENAS,MX | K46: 8100 | L46: 0 | M46: 180 | N46: 100 | O46: =SUM(K46:N46) -> 8380

Sheet YOSEF
P1: =SUM(N3:N344)-SUM(R4:R98) -> 381370
A2: REF/INV NO | B2: CUSTOMER | C2: CUSTOMER FOR | D2: BL | E2: CONTAINER | F2: ETD | G2: ETA | H2: SHIPPING LINE | I2: POL | J2: POD | K2: TOTAL COST | L2: PREVIO / INSURANCE | M2: EXW | N2: BILL AMT
A3: ZAY-25009 | B3: RUBEN ZAYAT | C3: YOSEF SENADO | D3: TLX | E3: MRSU7032351 | F3: 46004 | G3: 45664 | H3: MSK | I3: QINGDAO | J3: LAZARO CARDENAS,MX | K3: 2250 | L3: 180 | M3: 0 | N3: =SUM(K3+L3) -> 2430 | O3: 0 | Q3: DATE | R3: PAY
A4: AZO-25012 | B4: ABUD ZONANA | C4: YOSEF SENADO | D4: TLX | E4: KOCU4648528 | F4: 45668 | G4: 45691 | H4: HMM | I4: NINGBO | J4: LAZARO CARDENAS,MX | K4: 1500 | L4: 0 | M4: 0 | N4: =SUM(K4:L4) -> 1500 | O4: 0 | Q4: 46080 | R4: 43840
A5: AZO-25013 | B5: ABUD ZONANA | C5: YOSEF SENADO | D5: TLX | E5: TRHU5862460 | F5: 46033 | G5: 45691 | H5: ONE | I5: NINGBO | J5: LAZARO CARDENAS,MX | K5: 1500 | L5: 0 | M5: 0 | N5: =SUM(K5:L5) -> 1500 | O5: 0 | Q5: 46147 | R5: 149680
A6: ZAY-25010 | B6: RUBEN ZAYAT | C6: YOSEF SENADO | D6: TLX | E6: TCLU6370870 | F6: 45668 | G6: 45691 | H6: ONE | I6: NINGBO | J6: LAZARO CARDENAS,MX | K6: 1500 | L6: 180 | M6: 0 | N6: =SUM(K6:L6) -> 1680 | O6: 0 | Q6: 46188 | R6: 74700
A7: ZZH-25029 | B7: ALBERT JABAZ | C7: YOSEF SENADO | D7: TLX | E7: TRHU7318820 | F7: 46029 | G7: 45698 | H7: ONE | I7: XIAMEN | J7: LAZARO CARDENAS,MX | K7: 1600 | L7: 0 | M7: 0 | N7: =SUM(K7:L7) -> 1600 | O7: 0 | Q7: 46205 | R7: 76860
A8: GABRI-25005 | B8: GABIREL CATTAN | C8: YOSEF SENADO | D8: TLX | E8: HMMU6801563 | F8: 45668 | G8: 46056 | H8: HMM | I8: NINGBO | J8: LAZARO CARDENAS,MX | K8: 1500 | L8: 180 | M8: 0 | N8: =SUM(K8:L8) -> 1680 | O8: 0 | Q8: 46219 | R8: 55800
A9: AZO-26001 | B9: ABUD ZONANA | C9: YOSEF SENADO | D9: TLX | E9: HMMU6232554 | F9: 46033 | G9: 46056 | H9: ONE | I9: NINGBO | J9: LAZARO CARDENAS,MX | K9: 1500 | L9: 0 | M9: 0 | N9: =SUM(K9+L9) -> 1500 | O9: 0 | Q9: 46227 | R9: 151480
A10: SSA-25002 | B10: SAMUEL SACAL | C10: YOSEF SENADO | D10: TLX | E10: EGHU9760223 | F10: 46032 | G10: 46058 | H10: EMC | I10: SHANGHAI | J10: LAZARO CARDENAS,MX | K10: 1550 | L10: 180 | M10: 0 | N10: =SUM(K10:L10) -> 1730 | O10: 0 | Q10: 46255 | R10: 103991
A11: YTM-25011 | B11: MARCOS TUACHI (HIJO) | C11: YOSEF SENADO | D11: TLX | E11: EITU1800573 | F11: 45667 | G11: 46058 | H11: EMC | I11: SHANGHAI | J11: LAZARO CARDENAS,MX | K11: 1550 | L11: 180 | M11: 0 | N11: =SUM(K11:L11) -> 1730 | O11: 0 | Q11: 46272 | R11: 153220
A12: GABRI-26001 | B12: GABIREL CATTAN | C12: YOSEF SENADO | D12: TLX | E12: MRSU5813252 | F12: 46036 | G12: 46064 | H12: MSK | I12: SHENZHEN | J12: LAZARO CARDENAS,MX | K12: 1500 | L12: 0 | M12: 0 | N12: =SUM(K12:L12) -> 1500 | O12: 0 | Q12: 46289 | R12: 75020
A13: GAC-26001 | B13: GABIREL CATTAN | C13: YOSEF SENADO | D13: TLX | E13: TGBU4341124 | F13: 46042 | G13: 46068 | H13: COSCO | I13: NINGBO | J13: LAZARO CARDENAS,MX | K13: 1300 | L13: 180 | M13: 0 | N13: =SUM(K13:L13) -> 1480 | O13: 0 | Q13: 46293 | R13: 100212
A14: GAC-26002 | B14: GABIREL CATTAN | C14: YOSEF SENADO | D14: TLX | E14: TGBU8881157 | F14: 46042 | G14: 46068 | H14: COSCO | I14: NINGBO | J14: LAZARO CARDENAS,MX | K14: 1300 | L14: 180 | M14: 0 | N14: =SUM(K14:L14) -> 1480 | O14: 0
A15: GABRI-25006 | B15: GABIREL CATTAN | C15: YOSEF SENADO | D15: TLX | E15: XYLU8240489 | F15: 46038 | G15: 46068 | H15: COSCO | I15: TIANJIN | J15: LAZARO CARDENAS,MX | K15: 1350 | L15: 180 | M15: 0 | N15: =SUM(K15:L15) -> 1530 | O15: 0
A16: K-25043 | B16: LEON KUBURSI | C16: YOSEF SENADO | D16: TLX | E16: ONEU1199850 | F16: 45673 | G16: 46071 | H16: ONE | I16: XIAMEN | J16: LAZARO CARDENAS,MX | K16: 1300 | L16: 0 | M16: 0 | N16: =SUM(K16:L16) -> 1300 | O16: 0
A17: HASB-26001 | B17: ZUZU HASBANI | C17: YOSEF SENADO | D17: TLX | E17: TCLU9467756 | F17: 46036 | G17: 46074 | H17: ONE | I17: XIAMEN | J17: LAZARO CARDENAS,MX | K17: 1300 | L17: 100 | M17: 0 | N17: =SUM(K17:L17) -> 1400 | O17: 0
A18: ZAY-26003 | B18: RUBEN ZAYAT | C18: YOSEF SENADO | D18: TLX | E18: ONEU0131413 | F18: 46043 | G18: 46076 | H18: ONE | I18: YANTIAN | J18: LAZARO CARDENAS,MX | K18: 1250 | L18: 180 | M18: 0 | N18: =SUM(K18+L18) -> 1430 | O18: 0
A19: GAC-26004 | B19: GABIREL CATTAN | C19: YOSEF SENADO | D19: TLX | E19: EGSU1789311 | F19: 46047 | G19: 46078 | H19: EMC | I19: SHEKOU | J19: LAZARO CARDENAS,MX | K19: 1350 | L19: 180 | M19: 0 | N19: =SUM(K19+L19) -> 1530 | O19: 0
A20: GAC-26005 | B20: GABIREL CATTAN | C20: YOSEF SENADO | D20: TLX | E20: EMCU8560312 | F20: 46047 | G20: 46078 | H20: EMC | I20: SHEKOU | J20: LAZARO CARDENAS,MX | K20: 1350 | L20: 180 | M20: 0 | N20: =SUM(K20+L20) -> 1530 | O20: 0
A21: ZAY-26001 | B21: RUBEN ZAYAT | C21: YOSEF SENADO | D21: TLX | E21: KOCU4146896 | F21: 46054 | G21: 46079 | H21: HMM | I21: NINGBO | J21: LAZARO CARDENAS,MX | K21: 1450 | L21: 180 | M21: 0 | N21: =SUM(K21+L21) -> 1630 | O21: 0
A22: M-26001 | B22: MARCO TUACHI | C22: YOSEF SENADO | D22: TLX | E22: FCIU9962113 | F22: 46054 | G22: 46079 | H22: ONE | I22: NINGBO | J22: LAZARO CARDENAS,MX | K22: 1400 | L22: 0 | M22: 0 | N22: =SUM(K22+L22) -> 1400 | O22: 0
A23: M-26002 | B23: MARCO TUACHI | C23: YOSEF SENADO | D23: TLX | E23: ONEU6234208 | F23: 46054 | G23: 46079 | H23: ONE | I23: NINGBO | J23: LAZARO CARDENAS,MX | K23: 1400 | L23: 0 | M23: 0 | N23: =SUM(K23+L23) -> 1400 | O23: 0
A24: M-26003 | B24: MARCO TUACHI | C24: YOSEF SENADO | D24: TLX | E24: ONEU6233984 | F24: 46054 | G24: 46079 | H24: ONE | I24: NINGBO | J24: LAZARO CARDENAS,MX | K24: 1400 | L24: 0 | M24: 0 | N24: =SUM(K24+L24) -> 1400 | O24: 0
A25: MOYA-26001 | B25: Moy Askenazi | C25: YOSEF SENADO | D25: TLX | E25: MAGU5502372 | F25: 46054 | G25: 46082 | H25: COSCO | I25: NINGBO | J25: LAZARO CARDENAS,MX | K25: 1400 | L25: 180 | M25: 0 | N25: =SUM(K25+L25) -> 1580 | O25: 0
A26: MOYA-26002 | B26: Moy Askenazi | C26: YOSEF SENADO | D26: TLX | E26: CBHU7016295 | F26: 46054 | G26: 46082 | H26: COSCO | I26: NINGBO | J26: LAZARO CARDENAS,MX | K26: 1400 | L26: 180 | M26: 0 | N26: =SUM(K26+L26) -> 1580 | O26: 0
A27: ZAY-26005 | B27: RUBEN ZAYAT | C27: YOSEF SENADO | D27: TLX | E27: CSGU6065904 | F27: 46054 | G27: 46083 | H27: COSCO | I27: NINGBO | J27: LAZARO CARDENAS,MX | K27: 1400 | L27: 180 | M27: 0 | N27: =SUM(K27+L27) -> 1580 | O27: 0
A28: GAC-26003 | B28: GABIREL CATTAN | C28: YOSEF SENADO | D28: TLX | E28: HMMU4199523 | F28: 46054 | G28: 46084 | H28: HMM | I28: NINGBO | J28: LAZARO CARDENAS,MX | K28: 1450 | L28: 180 | M28: 0 | N28: =SUM(K28+L28) -> 1630 | O28: 0
A29: GABRI-26002 | B29: GABIREL CATTAN | C29: YOSEF SENADO | D29: TLX | E29: SUDU6922121 | F29: 46057 | G29: 46085 | H29: MSK | I29: YANTIAN | J29: LAZARO CARDENAS,MX | K29: 1400 | L29: 180 | M29: 0 | N29: =SUM(K29+L29) -> 1580 | O29: 0
... A122: ZAY-26028 | B122: RUBEN ZAYAT | C122: YOSEF SENADO | D122: TLX | E122: MEDU7391379 | F122: 46181 | G122: 46208 | H122: MSC | I122: NINGBO | J122: LAZARO CARDENAS,MX | K122: 6250 | L122: 180 | M122: 0 | N122: =SUM(K122+L122) -> 6430 | O122: 0
A123: ZAY-26030 | B123: RUBEN ZAYAT | C123: YOSEF SENADO | D123: TLX | E123: MSBU7152625 | F123: 46192 | G123: 46250 | H123: MSC | I123: NHAVA SHEVA, INDIA | J123: LAZARO CARDENAS,MX | K123: 5300 | L123: 0 | M123: 370 | N123: =SUM(K123+L123+M123) -> 5670 | O123: 370
A124: AZO-26009 | B124: ABUD ZONANA | C124: YOSEF SENADO | D124: TLX | E124: EITU8121260 | F124: 46185 | G124: 46215 | H124: EMC | I124: NINGBO | J124: LAZARO CARDENAS,MX | K124: 6600 | L124: 0 | M124: 0 | N124: =SUM(K124+L124) -> 6600 | O124: 0
A125: AZO-26010 | B125: ABUD ZONANA | C125: YOSEF SENADO | D125: TLX | E125: FCIU7533207 | F125: 46185 | G125: 46215 | H125: EMC | I125: NINGBO | J125: LAZARO CARDENAS,MX | K125: 6600 | L125: 0 | M125: 0 | N125: =SUM(K125+L125) -> 6600 | O125: 0
A126: HASB-26002 | B126: ZUZU HASBANI | C126: YOSEF SENADO | D126: TLX | E126: CAAU8104016 | F126: 46190 | G126: 46224 | H126: MSC | I126: XIAMEN | J126: LAZARO CARDENAS,MX | K126: 7000 | L126: 0 | M126: 0 | N126: =SUM(K126+L126) -> 7000 | O126: 0
A127: IS-SHIFF-26002 | B127: Cristóbal | C127: YOSEF SENADO | D127: TLX | E127: CAIU9501200 | F127: 46185 | G127: 46224 | H127: ONE | I127: SHENZHEN | J127: LAZARO CARDENAS,MX | K127: 6100 | L127: 280 | M127: 0 | N127: =SUM(K127+L127) -> 6380 | O127: 0
A128: IS-SHIFF-26003 | B128: Cristóbal | C128: YOSEF SENADO | D128: TLX | E128: GAOU6522960 | F128: 46185 | G128: 46224 | H128: ONE | I128: SHENZHEN | J128: LAZARO CARDENAS,MX | K128: 6100 | L128: 280 | M128: 0 | N128: =SUM(K128+L128) -> 6380 | O128: 0
A129: M-26025 | B129: MARCO TUACHI | C129: YOSEF SENADO | D129: TLX | E129: TXGU4307040 | F129: 46188 | G129: 46220 | H129: MSC | I129: NINGBO | J129: LAZARO CARDENAS,MX | K129: 6950 | L129: 0 | M129: 0 | N129: =SUM(K129+L129) -> 6950 | O129: 0
A130: ZUT-26004 | B130: Ezra Tussie | C130: YOSEF SENADO | D130: TLX | E130: MSNU6834572 | F130: 46190 | G130: 46224 | H130: MSC | I130: XIAMEN | J130: LAZARO CARDENAS,MX | K130: 7000 | L130: 180 | M130: 0 | N130: =SUM(K130+L130) -> 7180 | O130: 0
A131: ZUZU-26002 | B131: ZUZU HABAZ | C131: YOSEF SENADO | D131: TLX | E131: BEAU5906947 | F131: 46190 | G131: 46224 | H131: MSC | I131: XIAMEN | J131: LAZARO CARDENAS,MX | K131: 7000 | L131: 0 | M131: 0 | N131: =SUM(K131+L131) -> 7000 | O131: 0
A132: AZO-26011 | B132: ABUD ZONANA | C132: YOSEF SENADO | D132: TLX | E132: EITU8204473 | F132: 46207 | G132: 46229 | H132: EMC | I132: NINGBO | J132: LAZARO CARDENAS,MX | K132: 6300 | L132: 0 | M132: 0 | N132: =SUM(K132+L132) -> 6300 | O132: 0
...

Sheet YTM
O1: =SUM(M3:M339)-SUM(Q4:Q10) -> 0
A2: REF/INV NO | B2: CUSTOMER | C2: CUSTOMER FOR | D2: BL | E2: CONTAINER | F2: ETD | G2: ETA | H2: SHIPPING LINE | I2: POL | J2: POD | K2: TOTAL COST | L2: PREVIO / INSURANCE | M2: BILL AMT
A3: YTM-26003 | B3: YAACOB TUACHI | C3: ANHERST | D3: TLX | E3: TCLU5920294 | F3: 46212 | G3: 46242 | H3: MSC | I3: NINGBO | J3: LAZARO CARDENAS,MX | K3: 5800 | L3: 180 | M3: =SUM(K3+L3) -> 5980 | N3: =M3 -> 5980 | P3: DATE | Q3: PAY
P4: 46261 | Q4: 5980

Sheet HOLLY
M1: =SUM(M3:M48)-SUM(P4:P4) -> 0
A2: REF/INV NO | B2: CUSTOMER | C2: CUSTOMER FOR | D2: CONTAINER | E2: ETD | F2: ETA | G2: SHIPPING LINE | H2: POL | I2: POD | J2: TOTAL COST | K2: PREVIO | L2: INSURANCE | M2: BILL AMT
O3: DATE | P3: PAY

Sheet ARG
K1: =SUM(K3:K20)-SUM(N4:N10) -> 0
A2: REF/INV NO | B2: CUSTOMER | C2: CUSTOMER FOR | D2: BL | E2: CONTAINER | F2: ETD | G2: ETA | H2: SHIPPING LINE | I2: POL | J2: POD | K2: BILL AMT
M3: DATE | N3: PAY

Sheet IMPORT ONE
N1: =SUM(N3:N8) -> 0
A2: REF/INV NO | B2: CUSTOMER | C2: CUSTOMER FOR | D2: BL | E2: CONTAINER | F2: ETD | G2: ETA | H2: SHIPPING LINE | I2: POL | J2: POD | K2: Total Cost | L2: PREVIO/INSURANCE | M2: BILL AMT
P4: DATE | Q4: PAY

Sheet ELIAS LEVY
O1: =SUM(N3:N121)-SUM(R4:R15) -> 244415
A2: REF/INV NO | B2: CUSTOMER | C2: CUSTOMER FOR | D2: BL | E2: CONTAINER | F2: ETD | G2: ETA | H2: SHIPPING LINE | I2: POL | J2: POD | K2: TOTAL COST | L2: AMEND FEE | M2: INSURANCE | N2: BILL AMT
A3: CAVANA-25022/FANG3 | B3: ELIAS LEVY | C3: ELIAS LEVY | D3: SWB | E3: FFAU2699728 | F3: 46030 | G3: 46046 | H3: COSCO | I3: YANTIAN | J3: LONG BEACH | K3: 2500 | L3: 0 | M3: 100 | N3: =SUM(K3:M3) -> 2600 | O3: 0 | Q3: DATE | R3: PAY
A4: CAVANA-25021/C6 | B4: ELIAS LEVY | C4: ELIAS LEVY | D4: SWB | E4: OOCU7085973 | F4: 46030 | G4: 46046 | H4: COSCO | I4: YANTIAN | J4: LONG BEACH | K4: 3350 | L4: 0 | M4: 100 | N4: =SUM(K4:M4) -> 3450 | O4: 0 | Q4: 46182 | R4: =50000-1360 -> 48640
A5: STRANGER-25012/C7 | B5: ELIAS LEVY | C5: ELIAS LEVY | D5: SWB | E5: MSKU4753332 | F5: 46031 | G5: 46094 | H5: MSK | I5: NHAVA SHEVA,INDIA | J5: LOS ANGELES,CA | K5: 3350 | L5: 0 | M5: 100 | N5: =SUM(K5:M5) -> 3450 | O5: 0 | Q5: 46261 | R5: 40755
A6: STRANGER-25013/C8 | B6: ELIAS LEVY | C6: ELIAS LEVY | D6: SWB | E6: MAEU9261070 | F6: 46038 | G6: 46106 | H6: MSK | I6: NHAVA SHEVA,INDIA | J6: LOS ANGELES,CA | K6: 3250 | L6: 0 | M6: 0 | N6: =SUM(K6:M6) -> 3250 | O6: 0 | Q6: 46283 | R6: 40100
A7: CAVANA-26001/FANG4 | B7: ELIAS LEVY | C7: ELIAS LEVY | D7: SWB | E7: TCLU8603159 | F7: 46044 | G7: 46060 | H7: COSCO | I7: YANTIAN | J7: LONG BEACH | K7: 2600 | L7: 0 | M7: 0 | N7: =SUM(K7:M7) -> 2600 | O7: 0
A8: CAVANA-26002/C9 | B8: ELIAS LEVY | C8: ELIAS LEVY | D8: SWB | E8: FSCU7074684 | F8: 46053 | G8: 46074 | H8: CMA | I8: YANTIAN | J8: LOS ANGELES,CA | K8: 3300 | L8: 0 | M8: 0 | N8: =SUM(K8:M8) -> 3300 | O8: 0
A9: CAVANA-26003/FANG5 | B9: ELIAS LEVY | C9: ELIAS LEVY | D9: SWB | E9: DRYU4510031 | F9: 46053 | G9: 46074 | H9: CMA | I9: YANTIAN | J9: LOS ANGELES,CA | K9: 3300 | L9: 0 | M9: 0 | N9: =SUM(K9:M9) -> 3300 | O9: 0
A10: CAVANA-26005/FANG7 | B10: ELIAS LEVY | C10: ELIAS LEVY | D10: SWB | E10: CXDU2110219 | F10: 46060 | G10: 46080 | H10: CMA | I10: NINGBO | J10: LONG BEACH | K10: 3000 | L10: 0 | M10: 0 | N10: =SUM(K10:M10) -> 3000 | O10: 0
A11: STRANGER-26001/C10 | B11: ELIAS LEVY | C11: ELIAS LEVY | D11: SWB | E11: MAEU9240139 | F11: 46061 | G11: 46113 | H11: MSK | I11: NHAVA SHEVA,INDIA | J11: LOS ANGELES,CA | K11: 3200 | L11: 0 | M11: 0 | N11: =SUM(K11:M11) -> 3200 | O11: 0
A12: CAVANA-26007/C12 | B12: ELIAS LEVY | C12: ELIAS LEVY | D12: SWB | E12: ECMU8189428 | F12: 46063 | G12: 46079 | H12: CMA | I12: NINGBO | J12: LOS ANGELES,CA | K12: 3000 | L12: 0 | M12: 0 | N12: =SUM(K12:M12) -> 3000 | O12: 0
A13: CAVANA-26008/FANG8 | B13: ELIAS LEVY | C13: ELIAS LEVY | D13: SWB | E13: RFCU4045605 | F13: 46063 | G13: 46080 | H13: COSCO | I13: XIAMEN | J13: LONG BEACH | K13: 2550 | L13: 0 | M13: 100 | N13: =SUM(K13:M13) -> 2650 | O13: 0
A14: CAVANA-26006/C11 | B14: ELIAS LEVY | C14: ELIAS LEVY | D14: SWB | E14: ECMU8194553 | F14: 46063 | G14: 46091 | H14: CMA | I14: YANTIAN | J14: LOS ANGELES,CA | K14: 3080 | L14: 0 | M14: 0 | N14: =SUM(K14:M14) -> 3080 | O14: 0
A15: CAVANA-26004/FANG6 | B15: ELIAS LEVY | C15: ELIAS LEVY | D15: SWB | E15: ECMU8194105 | F15: 46063 | G15: 46092 | H15: CMA | I15: YANTIAN | J15: LOS ANGELES,CA | K15: 3000 | L15: 0 | M15: 0 | N15: =SUM(K15:M15) -> 3000 | O15: 0
A16: CAVANA-26009/C13 | B16: ELIAS LEVY | C16: ELIAS LEVY | D16: SWB | E16: CMAU5626408 | F16: 46072 | G16: 46104 | H16: CMA | I16: YANTIAN | J16: LOS ANGELES,CA | K16: 2550 | L16: 0 | M16: 100 | N16: =SUM(K16:M16) -> 2650 | O16: 0
A17: STRANGER-26002/C14 | B17: ELIAS LEVY | C17: ELIAS LEVY | D17: SWB | E17: HASU5137883 | F17: 46072 | G17: 46113 | H17: MSK | I17: TUTICORIN | J17: LOS ANGELES,CA | K17: 3250 | L17: 0 | M17: 100 | N17: =SUM(K17:M17) -> 3350 | O17: 0
A18: STRANGER-26003/C15 | B18: ELIAS LEVY | C18: ELIAS LEVY | D18: SWB | E18: MRSU5172652 | F18: 46088 | G18: 46127 | H18: MSK | I18: TUTICORIN | J18: LOS ANGELES,CA | K18: 3000 | L18: 0 | M18: 100 | N18: =SUM(K18:M18) -> 3100 | O18: 0
... A33: CAVANA-26020/FANG26 | B33: ELIAS LEVY | C33: ELIAS LEVY | D33: SWB | E33: CSNU9530526 | F33: 46235 | G33: 46253 | H33: COSCO | I33: YANTIAN | J33: LONG BEACH | K33: 8400 | L33: 0 | M33: 100 | N33: =SUM(K33:M33) -> 8500 | O33: 2605
A34: CAVANA-26021/FANG27 | B34: ELIAS LEVY | C34: ELIAS LEVY | D34: SWB | E34: CXDU2220900 | F34: 46235 | G34: 46253 | H34: COSCO | I34: YANTIAN | J34: LONG BEACH | K34: 8400 | L34: 0 | M34: 100 | N34: =SUM(K34:M34) -> 8500 | O34: =N34 -> 8500
A35: CAVANA-26023/FANG29 | B35: ELIAS LEVY | C35: ELIAS LEVY | D35: SWB | E35: CXDU2230955 | F35: 46238 | G35: 46254 | H35: COSCO | I35: YANTIAN | J35: LONG BEACH | K35: 8400 | L35: 0 | M35: 100 | N35: =SUM(K35:M35) -> 8500 | O35: =N35 -> 8500
A36: CAVANA-26024/FANG28 | B36: ELIAS LEVY | C36: ELIAS LEVY | D36: SWB | E36: OOLU5393799 | F36: 46238 | G36: 46254 | H36: COSCO | I36: YANTIAN | J36: LONG BEACH | K36: 8400 | L36: 0 | M36: 100 | N36: =SUM(K36:M36) -> 8500 | O36: =N36 -> 8500
A37: CAVANA-26025/FANG30 | B37: ELIAS LEVY | C37: ELIAS LEVY | D37: SWB | E37: CXDU2189532 | F37: 46238 | G37: 46254 | H37: COSCO | I37: YANTIAN | J37: LONG BEACH | K37: 8400 | L37: 0 | M37: 100 | N37: =SUM(K37:M37) -> 8500 | O37: =N37 -> 8500
A38: CAVANA-26027/FANG31 | B38: ELIAS LEVY | C38: ELIAS LEVY | D38: SWB | E38: CXDU2200204 | F38: 46238 | G38: 46254 | H38: COSCO | I38: YANTIAN | J38: LONG BEACH | K38: 8400 | L38: 0 | M38: 100 | N38: =SUM(K38:M38) -> 8500 | O38: =N38 -> 8500
A39: STRANGER-26008/C26 | B39: ELIAS LEVY | C39: ELIAS LEVY | D39: SWB | E39: MAEU9221545 | F39: 46241 | G39: 46292 | H39: MSK | I39: NHAVA SHEVA | J39: LOS ANGELES,CA | K39: 9050 | L39: 0 | M39: 0 | N39: =SUM(K39:M39) -> 9050 | O39: =N39 -> 9050
A40: CAVANA-26019/C32 | B40: ELIAS LEVY | C40: ELIAS LEVY | D40: SWB | E40: CSNU9521653 | F40: 46248 | G40: 46263 | H40: COSCO | I40: YANTIAN | J40: LONG BEACH | K40: 8400 | L40: 0 | M40: 100 | N40: =SUM(K40:M40) -> 8500 | O40: =N40 -> 8500
A41: CAVANA-26022/C33 | B41: ELIAS LEVY | C41: ELIAS LEVY | D41: SWB | E41: OOLU9079282 | F41: 46248 | G41: 46263 | H41: COSCO | I41: YANTIAN | J41: LONG BEACH | K41: 8400 | L41: 0 | M41: 0 | N41: =SUM(K41:M41) -> 8400 | O41: =N41 -> 8400
A42: STRANGER-26009/C28 | B42: ELIAS LEVY | C42: ELIAS LEVY | D42: SWB | E42: MAEU9284081 | F42: 46248 | G42: 46299 | H42: MSK | I42: NHAVA SHEVA | J42: LOS ANGELES,CA | K42: 10660 | L42: 0 | M42: 0 | N42: =SUM(K42:M42) -> 10660 | O42: =N42 -> 10660
A43: CAVANA-26028/FANG32 | B43: ELIAS LEVY | C43: ELIAS LEVY | D43: SWB | E43: SEGU5931094 | F43: 46249 | G43: 46269 | H43: ONE | I43: YANTIAN | J43: LONG BEACH | K43: 8200 | L43: 0 | M43: 100 | N43: =SUM(K43:M43) -> 8300 | O43: =N43 -> 8300
A44: CAVANA-26029/FANG33 | B44: ELIAS LEVY | C44: ELIAS LEVY | D44: SWB | E44: TCLU8419157 | F44: 46249 | G44: 46269 | H44: ONE | I44: YANTIAN | J44: LONG BEACH | K44: 8200 | L44: 0 | M44: 100 | N44: =SUM(K44:M44) -> 8300 | O44: =N44 -> 8300
A45: STRANGER-26011/C35 | B45: ELIAS LEVY | C45: ELIAS LEVY | D45: SWB | E45: MAEU9266555 | F45: 46253 | G45: 46295 | H45: MSK | I45: NHAVA SHEVA | J45: LOS ANGELES,CA | K45: 11200 | L45: 0 | M45: 0 | N45: =SUM(K45:M45) -> 11200 | O45: =N45 -> 11200
... A58: STRANGER-26014/C40 | B58: ELIAS LEVY | C58: ELIAS LEVY | D58: SWB | E58: MSKU4736103 | F58: 46293 | G58: 46341 | H58: MSK | I58: NHAVA SHEVA | J58: LOS ANGELES,US | K58: 14750 | L58: 0 | M58: 100 | N58: =SUM(K58:M58) -> 14850 | O58: =N58 -> 14850
A59: STRANGER-26015/C41 | B59: ELIAS LEVY | C59: ELIAS LEVY | D59: SWB | E59: WHSU6005650 | F59: 46299 | G59: 46351 | H59: MSK | I59: TUTICORIN | J59: LONG BEACH | L59: 0 | M59: 100 | N59: =SUM(K59:M59) -> 100 | O59: =N59 -> 100
A60: CAVANA-26039/C43 | B60: ELIAS LEVY | C60: ELIAS LEVY | D60: SWB | E60: MOEU1409896 | F60: 46298 | G60: 46314 | H60: ONE | I60: YANTIAN | J60: LOS ANGELES,CA | K60: 9300 | L60: 0 | M60: 100 | N60: =SUM(K60:M60) -> 9400 | O60: =N60 -> 9400

Sheet ALEJANDRO
M1: =SUM(M3:M29)-SUM(P4:P7) -> 0
A2: REF/INV NO | B2: CUSTOMER | C2: CUSTOMER FOR | D2: BL | E2: CONTAINER | F2: ETD | G2: ETA | H2: SHIPPING LINE | I2: POL | J2: POD | K2: TOTAL COST | L2: PREVIO | M2: BILL AMT
A3: JULIO-25001 | O3: DATE | P3: PAY
A4: JULIO-25002
A5: NINO-25001
A6: NINO-25002
A7: NINO-25003(M-RAN-250037)
A8: NINO-25004(M-RAN-250064)
A9: NINO-25005(M-RAN-250065)

Sheet JACK LEVY
O1: =SUM(N3:N140)-SUM(R4:R14) -> 0
A2: REF/INV NO | B2: CUSTOMER | C2: CUSTOMER FOR | D2: BL | E2: CONTAINER | F2: ETD | G2: ETA | H2: SHIPPING LINE | I2: POL | J2: POD | K2: TOTAL COST | L2: DETENTION FEE | M2: PREVIO/INSURANCE | N2: BILL AMT
A3: JISHOP-260006 | B3: JACK LEVY | C3: JACK LEVY | D3: SWB | E3: CSNU7098012 | F3: 46044 | G3: 46063 | H3: COSCO | I3: NINGBO | J3: LOS ANGELES,CA | K3: 2700 | L3: 0 | M3: 0 | N3: =SUM(K3:M3) -> 2700 | O3: 0 | Q3: DATE | R3: PAY
A4: JISHOP-260004 | B4: JACK LEVY | C4: JACK LEVY | D4: SWB | E4: ZCSU7716620 | F4: 46033 | G4: 46072 | H4: ZIM | I4: NINGBO | J4: HOUSTON | K4: 3900 | L4: 0 | M4: 100 | N4: =SUM(K4:M4) -> 4000 | O4: 0 | Q4: 46118 | R4: 25850
A5: JISHOP-260005 | B5: JACK LEVY | C5: JACK LEVY | D5: SWB | E5: TEMU7896297 | F5: 46036 | G5: 46073 | H5: COSCO | I5: QINGDAO | J5: HOUSTON | K5: 4000 | L5: 0 | M5: 100 | N5: =SUM(K5:M5) -> 4100 | O5: 0
A6: JISHOP-260003 | B6: JACK LEVY | C6: JACK LEVY | D6: SWB | E6: ECMU5692608 | F6: 46051 | G6: 46083 | H6: CMA | I6: NINGBO | J6: HOUSTON , TEXAS, US | K6: 3750 | L6: 0 | M6: 100 | N6: =SUM(K6:M6) -> 3850 | O6: 0
A7: JISHOP-260007 | B7: JACK LEVY | C7: JACK LEVY | D7: SWB | E7: TEMU8398160 | F7: 46051 | G7: 46083 | H7: CMA | I7: NINGBO | J7: HOUSTON , TEXAS, US | K7: 3750 | L7: 0 | M7: 100 | N7: =SUM(K7:M7) -> 3850 | O7: 0
A8: JISHOP-260002 | B8: JACK LEVY | C8: JACK LEVY | D8: SWB | E8: FFAU4504506 | F8: 46050 | G8: 46087 | H8: CMA | I8: TIANJIN | J8: HOUSTON , TEXAS, US | K8: 3750 | L8: 0 | M8: 100 | N8: =SUM(K8:M8) -> 3850 | O8: 0
A9: JISHOP-260001 | B9: JACK LEVY | C9: JACK LEVY | D9: SWB | E9: ZCSU7956908 | F9: 46054 | G9: 46097 | H9: ZIM | I9: NINGBO | J9: HOUSTON , TEXAS, US | K9: 3400 | L9: 0 | M9: 100 | N9: =SUM(K9:M9) -> 3500 | O9: 0

Sheet JHK
O1: =SUM(O3:O277) -> 68500
A2: REF/INV NO | B2: CUSTOMER | C2: CUSTOMER FOR | D2: BL | E2: CONTAINER | F2: ETD | G2: ETA | H2: SHIPPING LINE | I2: POL | J2: POD | K2: TOTAL COST | L2: RAIL | M2: INSURANCE | N2: BILL AMT
A3: JHK-25033 | B3: JACOBO HESKEL | C3: JHK | D3: TLX | E3: FCIU7382775 | F3: 45959 | G3: 45993 | H3: MSC | I3: XIAMEN | J3: LAZARO CARDENAS,MX | K3: 2300 | L3: 0 | M3: 0 | N3: 2300 | O3: 2300 | Q3: DATE | R3: PAY
A4: JHK-25042 | B4: JACOBO HESKEL | C4: JHK | D4: SWB | E4: BEAU5329212 | F4: 46024 | G4: 45691 | H4: ONE | I4: SHEKOU | J4: LAZARO CARDENAS,MX | K4: 1600 | L4: 0 | M4: 0 | N4: =SUM(K4:M4) -> 1600 | O4: have paid to ML-CHINA 11/08/26 | Q4: 46128 | R4: 26050
A5: JHK-25043 | B5: JACOBO HESKEL | C5: JHK | D5: SWB | E5: TRHU8306167 | F5: 46024 | G5: 45691 | H5: ONE | I5: SHEKOU | J5: LAZARO CARDENAS,MX | K5: 1600 | L5: 0 | M5: 0 | N5: =SUM(K5:M5) -> 1600 | O5: have paid to ML-CHINA 11/08/26 | Q5: 46245 | R5: 231900
A6: JHK-25036 | B6: JACOBO HESKEL | C6: JHK | D6: SWB | E6: EITU1288744 | F6: 45668 | G6: 45692 | H6: EMC | I6: SHENZHEN | J6: LAZARO CARDENAS,MX | K6: 1650 | L6: 0 | M6: 0 | N6: =SUM(K6:M6) -> 1650 | O6: =N6 -> 1650
A7: JHK-25040 | B7: JACOBO HESKEL | C7: JHK | D7: SWB | E7: HESU9989655 | F7: 45668 | G7: 45692 | H7: EMC | I7: SHENZHEN | J7: LAZARO CARDENAS,MX | K7: 1650 | L7: 0 | M7: 0 | N7: =SUM(K7:M7) -> 1650 | O7: =N7 -> 1650
A8: JHK-25044 | B8: JACOBO HESKEL | C8: JHK | D8: SWB | E8: CAAU6902260 | F8: 45661 | G8: 46053 | H8: EMC | I8: SHEKOU | J8: LAZARO CARDENAS,MX | K8: 1650 | L8: 0 | M8: 0 | N8: =SUM(K8:M8) -> 1650 | O8: have paid to ML-CHINA 11/08/26
A9: JHK-26001 | B9: JACOBO HESKEL | C9: JHK | D9: SWB | E9: GCXU6362524 | F9: 46033 | G9: 46057 | H9: EMC | I9: SHENZHEN | J9: LAZARO CARDENAS,MX | K9: 1650 | L9: 0 | M9: 0 | N9: =SUM(K9:M9) -> 1650 | O9: have paid to ML-CHINA 16/04/26
A10: JHK-26003 | B10: JACOBO HESKEL | C10: JHK | D10: SWB | E10: TLLU8647556 | F10: 46037 | G10: 46059 | H10: EMC | I10: NINGBO | J10: LAZARO,-ALL RAIL TO PANTACO | K10: 1500 | L10: 1700 | M10: 0 | N10: =SUM(K10:M10) -> 3200 | O10: have paid to ML-CHINA 16/04/26
A11: JHK-26002 | B11: JACOBO HESKEL | C11: JHK | D11: SWB | E11: TCNU3195215 | F11: 46036 | G11: 46064 | H11: MSK | I11: SHENZHEN | J11: LAZARO CARDENAS,MX | K11: 1600 | L11: 0 | M11: 0 | N11: =SUM(K11:M11) -> 1600 | O11: have paid to ML-CHINA 16/04/26
A12: JHK-26007 | B12: JACOBO HESKEL | C12: JHK | D12: SWB | E12: TLLU7876413 | F12: 46054 | G12: 46080 | H12: EMC | I12: SHEKOU | J12: LAZARO,-ALL RAIL TO PANTACO | K12: 1500 | L12: 1700 | M12: 0 | N12: =SUM(K12:M12) -> 3200 | O12: have paid to ML-CHINA 16/04/26
A13: JHK-26005 | B13: JACOBO HESKEL | C13: JHK | D13: SWB | E13: NYKU0821453 | F13: 46043 | G13: 46089 | H13: ONE | I13: YANTIAN | J13: LAZARO,-ALL RAIL TO PANTACO | K13: 1150 | L13: 1700 | M13: 0 | N13: =SUM(K13:M13) -> 2850 | O13: have paid to ML-CHINA 16/04/26
A14: JHK-26006 | B14: JACOBO HESKEL | C14: JHK | D14: SWB | E14: GCXU5205942 | F14: 46043 | G14: 46089 | H14: ONE | I14: YANTIAN | J14: LAZARO,-ALL RAIL TO PANTACO | K14: 1150 | L14: 1700 | M14: 0 | N14: =SUM(K14:M14) -> 2850 | O14: have paid to ML-CHINA 16/04/26
A15: JHK-26004 | B15: JACOBO HESKEL | C15: JHK | D15: SWB | E15: TGBU4387803 | F15: 46043 | G15: 46089 | H15: ONE | I15: YANTIAN | J15: LAZARO,-ALL RAIL TO PANTACO | K15: 1150 | L15: 1700 | M15: 0 | N15: =SUM(K15:M15) -> 2850 | O15: have paid to ML-CHINA 16/04/26
A16: JHK-26008 | B16: JACOBO HESKEL | C16: JHK | D16: SWB | E16: HMMU6033700 | F16: 46054 | G16: 46091 | H16: HMM | I16: NINGBO | J16: LAZARO CARDENAS,MX | K16: 1550 | L16: 0 | M16: 0 | N16: =SUM(K16:M16) -> 1550 | O16: have paid to ML-CHINA 16/04/26
A17: JHK-26010 | B17: JACOBO HESKEL | C17: JHK | D17: SWB | E17: MSMU4083123 | F17: 46066 | G17: 46096 | H17: MSC | I17: SHENZHEN | J17: LAZARO,-ALL RAIL TO PANTACO | K17: 2650 | L17: 1700 | M17: 0 | N17: =SUM(K17:M17) -> 4350 | O17: have paid to ML-CHINA 16/04/26
A18: JHK-26009 | B18: JACOBO HESKEL | C18: JHK | D18: SWB | E18: BEAU5505820 | F18: 46059 | G18: 46102 | H18: ONE | I18: SHENZHEN | J18: LAZARO,-ALL RAIL TO PANTACO | K18: 1200 | L18: 1700 | M18: 0 | N18: =SUM(K18:M18) -> 2900 | O18: have paid to ML-CHINA 16/04/26
A19: JHK-26011 | B19: JACOBO HESKEL | C19: JHK | D19: SWB | E19: DFSU7110425 | F19: 46122 | G19: 46154 | H19: MSC | I19: SHEKOU | J19: LAZARO,-ALL RAIL TO PANTACO | K19: 3500 | L19: 1700 | M19: 0 | N19: =SUM(K19:M19) -> 5200 | O19: have paid to ML-CHINA 11/08/26
A20: JHK-26012 | B20: JACOBO HESKEL | C20: JHK | D20: SWB | E20: TCLU4864468 | F20: 46127 | G20: 46159 | H20: ONE | I20: YANTIAN | J20: LAZARO CARDENAS,MX | K20: 3100 | L20: 0 | M20: 0 | N20: =SUM(K20:M20) -> 3100 | O20: =N20 -> 3100
